2015-11-04 11:29:02,371 INFO: - App: Building service dependencies...
2015-11-04 11:29:02,373 INFO: - App: Copying files and filling templates...
2015-11-04 11:29:02,391 INFO: - App: Building app image without Dockerfile...
2015-11-04 11:29:02,448 INFO: - App: Sending build context to Docker daemon 557.1 kBSending build context to Docker daemon 1.083 MBSending build context to Docker daemon 1.151 MBSending build context to Docker daemon 1.151 MB

2015-11-04 11:29:02,451 INFO: - App: Step 0 : FROM gcr.io/generic-notebooks/binder-base

2015-11-04 11:29:02,453 INFO: - App:  ---> 77377240dc83

2015-11-04 11:29:02,455 INFO: - App: Step 1 : ADD repo $HOME/notebooks

2015-11-04 11:29:02,649 INFO: - App:  ---> c3c2fe614e77

2015-11-04 11:29:02,660 INFO: - App: Removing intermediate container fa459a61eb31

2015-11-04 11:29:02,662 INFO: - App: Step 2 : USER root

2015-11-04 11:29:02,751 INFO: - App:  ---> Running in 0c759dd226a8

2015-11-04 11:29:02,795 INFO: - App:  ---> 7f8236326431

2015-11-04 11:29:02,809 INFO: - App: Removing intermediate container 0c759dd226a8

2015-11-04 11:29:02,811 INFO: - App: Step 3 : RUN chown -R main:main $HOME/notebooks

2015-11-04 11:29:02,880 INFO: - App:  ---> Running in bdd5d82200a6

2015-11-04 11:29:03,326 INFO: - App:  ---> 490f88f05cb4

2015-11-04 11:29:03,337 INFO: - App: Removing intermediate container bdd5d82200a6

2015-11-04 11:29:03,339 INFO: - App: Step 4 : USER main

2015-11-04 11:29:03,419 INFO: - App:  ---> Running in 7e4deb415fed

2015-11-04 11:29:03,467 INFO: - App:  ---> d4c91c15006a

2015-11-04 11:29:03,475 INFO: - App: Removing intermediate container 7e4deb415fed

2015-11-04 11:29:03,477 INFO: - App: Step 5 : RUN find $HOME/notebooks -name '*.ipynb' -exec ipython trust {} \;

2015-11-04 11:29:03,554 INFO: - App:  ---> Running in 458c7e80ba69

2015-11-04 11:29:04,053 INFO: - App: Signing notebook: /home/main/notebooks/notebooks/lab-01.ipynb

2015-11-04 11:29:04,291 INFO: - App: [TrustNotebookApp] ERROR | Notebook JSON is invalid: Additional properties are not allowed (u'name' was unexpected)

2015-11-04 11:29:04,293 INFO: - App: 

2015-11-04 11:29:04,295 INFO: - App: Failed validating u'additionalProperties' in schema:

2015-11-04 11:29:04,297 INFO: - App:     {u'additionalProperties': False,

2015-11-04 11:29:04,299 INFO: - App:      u'description': u'Stream output from a code cell.',

2015-11-04 11:29:04,301 INFO: - App:      u'properties': {u'output_type': {u'description': u'Type of cell output.',

2015-11-04 11:29:04,303 INFO: - App:                                       u'enum': [u'stream']},

2015-11-04 11:29:04,305 INFO: - App:                      u'stream': {u'description': u'The stream type/destination.',

2015-11-04 11:29:04,307 INFO: - App:                                  u'type': u'string'},

2015-11-04 11:29:04,311 INFO: - App:                      u'text': {u'$ref': u'#/definitions/misc/multiline_string',

2015-11-04 11:29:04,314 INFO: - App:                                u'description': u"The stream's text output, represented as an array of strings."}},

2015-11-04 11:29:04,316 INFO: - App:      u'required': [u'output_type', u'stream', u'text'],

2015-11-04 11:29:04,317 INFO: - App:      u'type': u'object'}

2015-11-04 11:29:04,319 INFO: - App: 

2015-11-04 11:29:04,321 INFO: - App: On instance:

2015-11-04 11:29:04,323 INFO: - App:     {u'name': u'stdout',

2015-11-04 11:29:04,325 INFO: - App:      u'output_type': u'stream',

2015-11-04 11:29:04,326 INFO: - App:      u'stream': u'stdout',

2015-11-04 11:29:04,328 INFO: - App:      u'text': u'1 9 4 5 2 3 8 6 7\n'}

2015-11-04 11:29:04,330 INFO: - App: Signing notebook: /home/main/notebooks/notebooks/Sudoku.ipynb

2015-11-04 11:29:04,582 INFO: - App: Signing notebook: /home/main/notebooks/notebooks/python-01.ipynb

2015-11-04 11:29:04,807 INFO: - App: Signing notebook: /home/main/notebooks/notebooks/python-04-ejercicios.ipynb

2015-11-04 11:29:05,063 INFO: - App: Signing notebook: /home/main/notebooks/notebooks/python-10.ipynb

2015-11-04 11:29:05,263 INFO: - App: Traceback (most recent call last):

2015-11-04 11:29:05,265 INFO: - App:   File "/home/main/anaconda/bin/ipython", line 6, in <module>

2015-11-04 11:29:05,268 INFO: - App: [91m    sys.exit(start_ipython())

2015-11-04 11:29:05,271 INFO: - App:   File "/home/main/anaconda/lib/python2.7/site-packages/IPython/__init__.py", line 120, in start_ipython

2015-11-04 11:29:05,275 INFO: - App: [91m    return launch_new_instance(argv=argv, **kwargs)

2015-11-04 11:29:05,277 INFO: - App:   File "/home/main/anaconda/lib/python2.7/site-packages/IPython/config/application.py", line 574, in launch_instance

2015-11-04 11:29:05,280 INFO: - App: [91m    app.start()

2015-11-04 11:29:05,281 INFO: - App: [91m  File "/home/main/anaconda/lib/python2.7/site-packages/IPython/terminal/ipapp.py", line 367, in start

2015-11-04 11:29:05,283 INFO: - App: [91m    return self.subapp.start()

2015-11-04 11:29:05,288 INFO: - App: [91m  File "/home/main/anaconda/lib/python2.7/site-packages/IPython/nbformat/sign.py", line 423, in start

2015-11-04 11:29:05,291 INFO: - App: [91m    self.sign_notebook(notebook_path)

2015-11-04 11:29:05,294 INFO: - App: [91m  File "/home/main/anaconda/lib/python2.7/site-packages/IPython/nbformat/sign.py", line 395, in sign_notebook

2015-11-04 11:29:05,298 INFO: - App:     if not os.path.exists(notebook_path):

2015-11-04 11:29:05,299 INFO: - App:   File "/home/main/anaconda/lib/python2.7/genericpath.py", line 26, in exists

2015-11-04 11:29:05,302 INFO: - App: [91m    os.stat(path)

2015-11-04 11:29:05,303 INFO: - App: [91mUnicodeEncodeError: 'ascii' codec can't encode characters in position 51-52: ordinal not in range(128)

2015-11-04 11:29:05,305 INFO: - App: [91m

2015-11-04 11:29:05,307 INFO: - App: If you suspect this is an IPython bug, please report it at:

2015-11-04 11:29:05,309 INFO: - App:     https://github.com/ipython/ipython/issues

2015-11-04 11:29:05,311 INFO: - App: or send an email to the mailing list at ipython-dev@scipy.org

2015-11-04 11:29:05,314 INFO: - App: 

2015-11-04 11:29:05,319 INFO: - App: You can print a more detailed traceback right now with "%tb", or use "%debug"

2015-11-04 11:29:05,321 INFO: - App: to interactively debug it.

2015-11-04 11:29:05,323 INFO: - App: 

2015-11-04 11:29:05,325 INFO: - App: Extra-detailed tracebacks for bug-reporting purposes can be enabled via:

2015-11-04 11:29:05,326 INFO: - App:     c.Application.verbose_crash=True

2015-11-04 11:29:05,328 INFO: - App: 

2015-11-04 11:29:05,519 INFO: - App: Signing notebook: /home/main/notebooks/notebooks/python-02.ipynb

2015-11-04 11:29:05,727 INFO: - App: Traceback (most recent call last):

2015-11-04 11:29:05,731 INFO: - App:   File "/home/main/anaconda/bin/ipython", line 6, in <module>

2015-11-04 11:29:05,732 INFO: - App: [91m    sys.exit(start_ipython())

2015-11-04 11:29:05,734 INFO: - App:   File "/home/main/anaconda/lib/python2.7/site-packages/IPython/__init__.py", line 120, in start_ipython

2015-11-04 11:29:05,736 INFO: - App: [91m    return launch_new_instance(argv=argv, **kwargs)

2015-11-04 11:29:05,738 INFO: - App:   File "/home/main/anaconda/lib/python2.7/site-packages/IPython/config/application.py", line 574, in launch_instance

2015-11-04 11:29:05,740 INFO: - App: [91m    app.start()

2015-11-04 11:29:05,742 INFO: - App: [91m  File "/home/main/anaconda/lib/python2.7/site-packages/IPython/terminal/ipapp.py", line 367, in start

2015-11-04 11:29:05,744 INFO: - App: [91m    return self.subapp.start()

2015-11-04 11:29:05,746 INFO: - App: [91m  File "/home/main/anaconda/lib/python2.7/site-packages/IPython/nbformat/sign.py", line 423, in start

2015-11-04 11:29:05,748 INFO: - App: [91m    self.sign_notebook(notebook_path)

2015-11-04 11:29:05,750 INFO: - App: [91m  File "/home/main/anaconda/lib/python2.7/site-packages/IPython/nbformat/sign.py", line 395, in sign_notebook

2015-11-04 11:29:05,754 INFO: - App:     if not os.path.exists(notebook_path):

2015-11-04 11:29:05,757 INFO: - App:   File "/home/main/anaconda/lib/python2.7/genericpath.py", line 26, in exists

2015-11-04 11:29:05,759 INFO: - App: [91m    os.stat(path)

2015-11-04 11:29:05,761 INFO: - App: [91mUnicodeEncodeError: 'ascii' codec can't encode characters in position 51-52: ordinal not in range(128)

2015-11-04 11:29:05,763 INFO: - App: 

2015-11-04 11:29:05,765 INFO: - App: If you suspect this is an IPython bug, please report it at:

2015-11-04 11:29:05,767 INFO: - App:     https://github.com/ipython/ipython/issues

2015-11-04 11:29:05,769 INFO: - App: or send an email to the mailing list at ipython-dev@scipy.org

2015-11-04 11:29:05,772 INFO: - App: 

2015-11-04 11:29:05,774 INFO: - App: You can print a more detailed traceback right now with "%tb", or use "%debug"

2015-11-04 11:29:05,776 INFO: - App: to interactively debug it.

2015-11-04 11:29:05,778 INFO: - App: 

2015-11-04 11:29:05,781 INFO: - App: Extra-detailed tracebacks for bug-reporting purposes can be enabled via:

2015-11-04 11:29:05,783 INFO: - App:     c.Application.verbose_crash=True

2015-11-04 11:29:05,785 INFO: - App: 

2015-11-04 11:29:05,959 INFO: - App: Signing notebook: /home/main/notebooks/notebooks/python-00.ipynb

2015-11-04 11:29:06,182 INFO: - App: Signing notebook: /home/main/notebooks/notebooks/lab-03.ipynb

2015-11-04 11:29:06,446 INFO: - App: Signing notebook: /home/main/notebooks/notebooks/python-04.ipynb

2015-11-04 11:29:06,712 INFO: - App: Signing notebook: /home/main/notebooks/notebooks/Paseo.ipynb

2015-11-04 11:29:06,931 INFO: - App: Signing notebook: /home/main/notebooks/notebooks/Resumen.ipynb

2015-11-04 11:29:07,167 INFO: - App: Signing notebook: /home/main/notebooks/notebooks/Problema de las 8 damas.ipynb

2015-11-04 11:29:07,395 INFO: - App: Signing notebook: /home/main/notebooks/notebooks/lab-02.ipynb

2015-11-04 11:29:07,630 INFO: - App: Signing notebook: /home/main/notebooks/notebooks/BisectionSearch.ipynb

2015-11-04 11:29:07,849 INFO: - App: Traceback (most recent call last):

2015-11-04 11:29:07,851 INFO: - App:   File "/home/main/anaconda/bin/ipython", line 6, in <module>

2015-11-04 11:29:07,853 INFO: - App: [91m    sys.exit(start_ipython())

2015-11-04 11:29:07,855 INFO: - App:   File "/home/main/anaconda/lib/python2.7/site-packages/IPython/__init__.py", line 120, in start_ipython

2015-11-04 11:29:07,857 INFO: - App:     return launch_new_instance(argv=argv, **kwargs)

2015-11-04 11:29:07,859 INFO: - App:   File "/home/main/anaconda/lib/python2.7/site-packages/IPython/config/application.py", line 574, in launch_instance

2015-11-04 11:29:07,861 INFO: - App: [91m    app.start()

2015-11-04 11:29:07,863 INFO: - App: [91m  File "/home/main/anaconda/lib/python2.7/site-packages/IPython/terminal/ipapp.py", line 367, in start

2015-11-04 11:29:07,865 INFO: - App: [91m    return self.subapp.start()

2015-11-04 11:29:07,867 INFO: - App: [91m  File "/home/main/anaconda/lib/python2.7/site-packages/IPython/nbformat/sign.py", line 423, in start

2015-11-04 11:29:07,870 INFO: - App: [91m    self.sign_notebook(notebook_path)

2015-11-04 11:29:07,872 INFO: - App: [91m  File "/home/main/anaconda/lib/python2.7/site-packages/IPython/nbformat/sign.py", line 395, in sign_notebook

2015-11-04 11:29:07,874 INFO: - App:     if not os.path.exists(notebook_path):

2015-11-04 11:29:07,876 INFO: - App:   File "/home/main/anaconda/lib/python2.7/genericpath.py", line 26, in exists

2015-11-04 11:29:07,878 INFO: - App: [91m    os.stat(path)

2015-11-04 11:29:07,880 INFO: - App: [91mUnicodeEncodeError: 'ascii' codec can't encode characters in position 51-52: ordinal not in range(128)

2015-11-04 11:29:07,882 INFO: - App: [91m

2015-11-04 11:29:07,883 INFO: - App: If you suspect this is an IPython bug, please report it at:

2015-11-04 11:29:07,886 INFO: - App:     https://github.com/ipython/ipython/issues

2015-11-04 11:29:07,889 INFO: - App: or send an email to the mailing list at ipython-dev@scipy.org

2015-11-04 11:29:07,892 INFO: - App: 

2015-11-04 11:29:07,894 INFO: - App: You can print a more detailed traceback right now with "%tb", or use "%debug"

2015-11-04 11:29:07,896 INFO: - App: to interactively debug it.

2015-11-04 11:29:07,898 INFO: - App: 

2015-11-04 11:29:07,904 INFO: - App: Extra-detailed tracebacks for bug-reporting purposes can be enabled via:

2015-11-04 11:29:07,905 INFO: - App:     c.Application.verbose_crash=True

2015-11-04 11:29:07,907 INFO: - App: 

2015-11-04 11:29:08,106 INFO: - App: Signing notebook: /home/main/notebooks/notebooks/python-05-06-07.ipynb

2015-11-04 11:29:08,431 INFO: - App: Signing notebook: /home/main/notebooks/notebooks/python-09.ipynb

2015-11-04 11:29:08,709 INFO: - App:  ---> ff01f06b4c52

2015-11-04 11:29:08,719 INFO: - App: Removing intermediate container 458c7e80ba69

2015-11-04 11:29:08,725 INFO: - App: Step 6 : WORKDIR $HOME/notebooks

2015-11-04 11:29:08,791 INFO: - App:  ---> Running in a10167c723bb

2015-11-04 11:29:08,839 INFO: - App:  ---> 1e955fa15eca

2015-11-04 11:29:08,848 INFO: - App: Removing intermediate container a10167c723bb

2015-11-04 11:29:08,849 INFO: - App: Successfully built 1e955fa15eca

2015-11-04 11:29:08,857 INFO: - App: Squashing and pushing gcr.io/generic-notebooks/franciscomoya-informatica to private registry...
2015-11-04 11:29:15,034 INFO: - App: Preloading app image onto all nodes...
2015-11-04 11:29:18,820 INFO: - App: Successfully built app franciscomoya-informatica
2015-11-04 11:37:21,032 INFO: - App: Building service dependencies...
2015-11-04 11:37:21,035 INFO: - App: Copying files and filling templates...
2015-11-04 11:37:21,051 INFO: - App: Building app image without Dockerfile...
2015-11-04 11:37:21,113 INFO: - App: Sending build context to Docker daemon 557.1 kBSending build context to Docker daemon 1.083 MBSending build context to Docker daemon 1.151 MBSending build context to Docker daemon 1.151 MB

2015-11-04 11:37:21,115 INFO: - App: Step 0 : FROM gcr.io/generic-notebooks/binder-base

2015-11-04 11:37:21,116 INFO: - App:  ---> 77377240dc83

2015-11-04 11:37:21,118 INFO: - App: Step 1 : ADD repo $HOME/notebooks

2015-11-04 11:37:21,296 INFO: - App:  ---> b6916df9d111

2015-11-04 11:37:21,305 INFO: - App: Removing intermediate container d63154c8a4cf

2015-11-04 11:37:21,307 INFO: - App: Step 2 : USER root

2015-11-04 11:37:21,383 INFO: - App:  ---> Running in da327a9f1c1a

2015-11-04 11:37:21,431 INFO: - App:  ---> 8408b0796b32

2015-11-04 11:37:21,439 INFO: - App: Removing intermediate container da327a9f1c1a

2015-11-04 11:37:21,441 INFO: - App: Step 3 : RUN chown -R main:main $HOME/notebooks

2015-11-04 11:37:21,523 INFO: - App:  ---> Running in dc32ad94962e

2015-11-04 11:37:21,976 INFO: - App:  ---> 8c1194bf2af3

2015-11-04 11:37:21,985 INFO: - App: Removing intermediate container dc32ad94962e

2015-11-04 11:37:21,995 INFO: - App: Step 4 : USER main

2015-11-04 11:37:22,064 INFO: - App:  ---> Running in a9ab1be7f921

2015-11-04 11:37:22,111 INFO: - App:  ---> 4a7cb8f80128

2015-11-04 11:37:22,119 INFO: - App: Removing intermediate container a9ab1be7f921

2015-11-04 11:37:22,121 INFO: - App: Step 5 : RUN find $HOME/notebooks -name '*.ipynb' -exec ipython trust {} \;

2015-11-04 11:37:22,207 INFO: - App:  ---> Running in 15ea04608443

2015-11-04 11:37:22,719 INFO: - App: Signing notebook: /home/main/notebooks/notebooks/lab-01.ipynb

2015-11-04 11:37:22,962 INFO: - App: [TrustNotebookApp] ERROR | Notebook JSON is invalid: Additional properties are not allowed (u'name' was unexpected)

2015-11-04 11:37:22,967 INFO: - App: 

2015-11-04 11:37:22,969 INFO: - App: Failed validating u'additionalProperties' in schema:

2015-11-04 11:37:22,971 INFO: - App:     {u'additionalProperties': False,

2015-11-04 11:37:22,973 INFO: - App:      u'description': u'Stream output from a code cell.',

2015-11-04 11:37:22,974 INFO: - App:      u'properties': {u'output_type': {u'description': u'Type of cell output.',

2015-11-04 11:37:22,976 INFO: - App:                                       u'enum': [u'stream']},

2015-11-04 11:37:22,978 INFO: - App:                      u'stream': {u'description': u'The stream type/destination.',

2015-11-04 11:37:22,981 INFO: - App:                                  u'type': u'string'},

2015-11-04 11:37:22,983 INFO: - App:                      u'text': {u'$ref': u'#/definitions/misc/multiline_string',

2015-11-04 11:37:22,985 INFO: - App:                                u'description': u"The stream's text output, represented as an array of strings."}},

2015-11-04 11:37:22,987 INFO: - App:      u'required': [u'output_type', u'stream', u'text'],

2015-11-04 11:37:22,988 INFO: - App:      u'type': u'object'}

2015-11-04 11:37:22,990 INFO: - App: 

2015-11-04 11:37:22,992 INFO: - App: On instance:

2015-11-04 11:37:22,994 INFO: - App:     {u'name': u'stdout',

2015-11-04 11:37:22,995 INFO: - App:      u'output_type': u'stream',

2015-11-04 11:37:22,998 INFO: - App:      u'stream': u'stdout',

2015-11-04 11:37:22,999 INFO: - App:      u'text': u'1 9 4 5 2 3 8 6 7\n'}

2015-11-04 11:37:23,001 INFO: - App: Signing notebook: /home/main/notebooks/notebooks/Sudoku.ipynb

2015-11-04 11:37:23,250 INFO: - App: Signing notebook: /home/main/notebooks/notebooks/python-01.ipynb

2015-11-04 11:37:23,473 INFO: - App: Signing notebook: /home/main/notebooks/notebooks/python-04-ejercicios.ipynb

2015-11-04 11:37:23,708 INFO: - App: Signing notebook: /home/main/notebooks/notebooks/python-10.ipynb

2015-11-04 11:37:23,911 INFO: - App: Traceback (most recent call last):

2015-11-04 11:37:23,913 INFO: - App:   File "/home/main/anaconda/bin/ipython", line 6, in <module>

2015-11-04 11:37:23,918 INFO: - App: [91m    sys.exit(start_ipython())

2015-11-04 11:37:23,920 INFO: - App:   File "/home/main/anaconda/lib/python2.7/site-packages/IPython/__init__.py", line 120, in start_ipython

2015-11-04 11:37:23,921 INFO: - App: [91m    return launch_new_instance(argv=argv, **kwargs)

2015-11-04 11:37:23,925 INFO: - App:   File "/home/main/anaconda/lib/python2.7/site-packages/IPython/config/application.py", line 574, in launch_instance

2015-11-04 11:37:23,931 INFO: - App: [91m    app.start()

2015-11-04 11:37:23,936 INFO: - App: [91m  File "/home/main/anaconda/lib/python2.7/site-packages/IPython/terminal/ipapp.py", line 367, in start

2015-11-04 11:37:23,939 INFO: - App: [91m    return self.subapp.start()

2015-11-04 11:37:23,944 INFO: - App: [91m  File "/home/main/anaconda/lib/python2.7/site-packages/IPython/nbformat/sign.py", line 423, in start

2015-11-04 11:37:23,947 INFO: - App: [91m    self.sign_notebook(notebook_path)

2015-11-04 11:37:23,954 INFO: - App: [91m  File "/home/main/anaconda/lib/python2.7/site-packages/IPython/nbformat/sign.py", line 395, in sign_notebook

2015-11-04 11:37:23,956 INFO: - App:     if not os.path.exists(notebook_path):

2015-11-04 11:37:23,959 INFO: - App:   File "/home/main/anaconda/lib/python2.7/genericpath.py", line 26, in exists

2015-11-04 11:37:23,973 INFO: - App:     os.stat(path)

2015-11-04 11:37:23,979 INFO: - App: [91mUnicodeEncodeError: 'ascii' codec can't encode characters in position 51-52: ordinal not in range(128)

2015-11-04 11:37:23,987 INFO: - App: 

2015-11-04 11:37:24,004 INFO: - App: If you suspect this is an IPython bug, please report it at:

2015-11-04 11:37:24,008 INFO: - App:     https://github.com/ipython/ipython/issues

2015-11-04 11:37:24,014 INFO: - App: or send an email to the mailing list at ipython-dev@scipy.org

2015-11-04 11:37:24,021 INFO: - App: 

2015-11-04 11:37:24,034 INFO: - App: You can print a more detailed traceback right now with "%tb", or use "%debug"

2015-11-04 11:37:24,059 INFO: - App: to interactively debug it.

2015-11-04 11:37:24,065 INFO: - App: 

2015-11-04 11:37:24,074 INFO: - App: Extra-detailed tracebacks for bug-reporting purposes can be enabled via:

2015-11-04 11:37:24,076 INFO: - App:     c.Application.verbose_crash=True

2015-11-04 11:37:24,079 INFO: - App: 

2015-11-04 11:37:24,170 INFO: - App: Signing notebook: /home/main/notebooks/notebooks/python-02.ipynb

2015-11-04 11:37:24,386 INFO: - App: Traceback (most recent call last):

2015-11-04 11:37:24,388 INFO: - App:   File "/home/main/anaconda/bin/ipython", line 6, in <module>

2015-11-04 11:37:24,390 INFO: - App: [91m    sys.exit(start_ipython())

2015-11-04 11:37:24,392 INFO: - App:   File "/home/main/anaconda/lib/python2.7/site-packages/IPython/__init__.py", line 120, in start_ipython

2015-11-04 11:37:24,398 INFO: - App: [91m    return launch_new_instance(argv=argv, **kwargs)

2015-11-04 11:37:24,400 INFO: - App:   File "/home/main/anaconda/lib/python2.7/site-packages/IPython/config/application.py", line 574, in launch_instance

2015-11-04 11:37:24,402 INFO: - App: [91m    app.start()

2015-11-04 11:37:24,404 INFO: - App: [91m  File "/home/main/anaconda/lib/python2.7/site-packages/IPython/terminal/ipapp.py", line 367, in start

2015-11-04 11:37:24,406 INFO: - App: [91m    return self.subapp.start()

2015-11-04 11:37:24,411 INFO: - App: [91m  File "/home/main/anaconda/lib/python2.7/site-packages/IPython/nbformat/sign.py", line 423, in start

2015-11-04 11:37:24,417 INFO: - App: [91m    self.sign_notebook(notebook_path)

2015-11-04 11:37:24,419 INFO: - App: [91m  File "/home/main/anaconda/lib/python2.7/site-packages/IPython/nbformat/sign.py", line 395, in sign_notebook

2015-11-04 11:37:24,424 INFO: - App:     if not os.path.exists(notebook_path):

2015-11-04 11:37:24,426 INFO: - App: [91m  File "/home/main/anaconda/lib/python2.7/genericpath.py", line 26, in exists

2015-11-04 11:37:24,428 INFO: - App: [91m    os.stat(path)

2015-11-04 11:37:24,430 INFO: - App: [91mUnicodeEncodeError: 'ascii' codec can't encode characters in position 51-52: ordinal not in range(128)

2015-11-04 11:37:24,431 INFO: - App: [91m

2015-11-04 11:37:24,433 INFO: - App: If you suspect this is an IPython bug, please report it at:

2015-11-04 11:37:24,435 INFO: - App:     https://github.com/ipython/ipython/issues

2015-11-04 11:37:24,437 INFO: - App: or send an email to the mailing list at ipython-dev@scipy.org

2015-11-04 11:37:24,438 INFO: - App: 

2015-11-04 11:37:24,447 INFO: - App: You can print a more detailed traceback right now with "%tb", or use "%debug"

2015-11-04 11:37:24,453 INFO: - App: to interactively debug it.

2015-11-04 11:37:24,455 INFO: - App: 

2015-11-04 11:37:24,458 INFO: - App: Extra-detailed tracebacks for bug-reporting purposes can be enabled via:

2015-11-04 11:37:24,459 INFO: - App:     c.Application.verbose_crash=True

2015-11-04 11:37:24,462 INFO: - App: 

2015-11-04 11:37:24,610 INFO: - App: Signing notebook: /home/main/notebooks/notebooks/python-00.ipynb

2015-11-04 11:37:24,823 INFO: - App: Signing notebook: /home/main/notebooks/notebooks/lab-03.ipynb

2015-11-04 11:37:25,080 INFO: - App: Signing notebook: /home/main/notebooks/notebooks/python-04.ipynb

2015-11-04 11:37:25,332 INFO: - App: Signing notebook: /home/main/notebooks/notebooks/Paseo.ipynb

2015-11-04 11:37:25,564 INFO: - App: Signing notebook: /home/main/notebooks/notebooks/Resumen.ipynb

2015-11-04 11:37:25,799 INFO: - App: Signing notebook: /home/main/notebooks/notebooks/Problema de las 8 damas.ipynb

2015-11-04 11:37:26,017 INFO: - App: Signing notebook: /home/main/notebooks/notebooks/lab-02.ipynb

2015-11-04 11:37:26,252 INFO: - App: Signing notebook: /home/main/notebooks/notebooks/BisectionSearch.ipynb

2015-11-04 11:37:26,461 INFO: - App: Traceback (most recent call last):

2015-11-04 11:37:26,464 INFO: - App:   File "/home/main/anaconda/bin/ipython", line 6, in <module>

2015-11-04 11:37:26,466 INFO: - App: [91m    sys.exit(start_ipython())

2015-11-04 11:37:26,467 INFO: - App:   File "/home/main/anaconda/lib/python2.7/site-packages/IPython/__init__.py", line 120, in start_ipython

2015-11-04 11:37:26,470 INFO: - App: [91m    return launch_new_instance(argv=argv, **kwargs)

2015-11-04 11:37:26,477 INFO: - App: [91m  File "/home/main/anaconda/lib/python2.7/site-packages/IPython/config/application.py", line 574, in launch_instance

2015-11-04 11:37:26,479 INFO: - App: [91m    app.start()

2015-11-04 11:37:26,482 INFO: - App: [91m  File "/home/main/anaconda/lib/python2.7/site-packages/IPython/terminal/ipapp.py", line 367, in start

2015-11-04 11:37:26,485 INFO: - App: [91m    return self.subapp.start()

2015-11-04 11:37:26,486 INFO: - App: [91m  File "/home/main/anaconda/lib/python2.7/site-packages/IPython/nbformat/sign.py", line 423, in start

2015-11-04 11:37:26,495 INFO: - App: [91m    self.sign_notebook(notebook_path)

2015-11-04 11:37:26,497 INFO: - App: [91m  File "/home/main/anaconda/lib/python2.7/site-packages/IPython/nbformat/sign.py", line 395, in sign_notebook

2015-11-04 11:37:26,498 INFO: - App:     if not os.path.exists(notebook_path):

2015-11-04 11:37:26,502 INFO: - App:   File "/home/main/anaconda/lib/python2.7/genericpath.py", line 26, in exists

2015-11-04 11:37:26,505 INFO: - App: [91m    os.stat(path)

2015-11-04 11:37:26,507 INFO: - App: [91mUnicodeEncodeError: 'ascii' codec can't encode characters in position 51-52: ordinal not in range(128)

2015-11-04 11:37:26,510 INFO: - App: [91m

2015-11-04 11:37:26,511 INFO: - App: If you suspect this is an IPython bug, please report it at:

2015-11-04 11:37:26,513 INFO: - App:     https://github.com/ipython/ipython/issues

2015-11-04 11:37:26,515 INFO: - App: or send an email to the mailing list at ipython-dev@scipy.org

2015-11-04 11:37:26,517 INFO: - App: 

2015-11-04 11:37:26,519 INFO: - App: You can print a more detailed traceback right now with "%tb", or use "%debug"

2015-11-04 11:37:26,520 INFO: - App: to interactively debug it.

2015-11-04 11:37:26,522 INFO: - App: 

2015-11-04 11:37:26,524 INFO: - App: Extra-detailed tracebacks for bug-reporting purposes can be enabled via:

2015-11-04 11:37:26,526 INFO: - App:     c.Application.verbose_crash=True

2015-11-04 11:37:26,528 INFO: - App: 

2015-11-04 11:37:26,732 INFO: - App: Signing notebook: /home/main/notebooks/notebooks/python-05-06-07.ipynb

2015-11-04 11:37:27,072 INFO: - App: Signing notebook: /home/main/notebooks/notebooks/python-09.ipynb

2015-11-04 11:37:27,333 INFO: - App:  ---> fe4d6c48fff8

2015-11-04 11:37:27,342 INFO: - App: Removing intermediate container 15ea04608443

2015-11-04 11:37:27,343 INFO: - App: Step 6 : WORKDIR $HOME/notebooks

2015-11-04 11:37:27,411 INFO: - App:  ---> Running in f9e455101d6c

2015-11-04 11:37:27,458 INFO: - App:  ---> b1d5aaf79c63

2015-11-04 11:37:27,466 INFO: - App: Removing intermediate container f9e455101d6c

2015-11-04 11:37:27,471 INFO: - App: Successfully built b1d5aaf79c63

2015-11-04 11:37:27,476 INFO: - App: Squashing and pushing gcr.io/generic-notebooks/franciscomoya-informatica to private registry...
2015-11-04 11:37:34,257 INFO: - App: Preloading app image onto all nodes...
2015-11-04 11:37:44,944 INFO: - App: Successfully built app franciscomoya-informatica
